<?xml version="1.0"?>
<robot name="homework1">

<material name="pink">
    <color rgba="0.92 0.01 0.98 1"/>
  </material>
  <material name="dark">
    <color rgba="0.19 0 0.38 1"/>
  </material>
  <material name="white">
    <color rgba="1 1 1 1"/>
  </material>

  <link name="base_link">
    <visual>
      <geometry>
        <box size ="0.6 0.6 0.6"/>
      </geometry>
      <material name="dark"/>
    </visual>
    <collision>
      <geometry>
        <box size ="0.6 0.6 0.6"/>
      </geometry>
    </collision>
    <inertial>
      <mass value="10"/>
      <inertia ixx="1.0" ixy="0.0" ixz="0.0" iyy="1.0" iyz="0.0" izz="1.0"/>
    </inertial>
  </link>

  <link name="right_cylinder">
    <visual>
      <geometry>
        <cylinder length="0.6" radius="0.1"/>
      </geometry>
      <origin xyz="0 0 0.3"/>
      <material name="pink"/>
    </visual>
  </link>

  <joint name="base_to_right_cylinder" type="revolute">
    <axis xyz="1 0 0"/>
    <limit effort="1000.0" lower="-0.7" upper="0" velocity="0.5"/>
    <parent link="base_link"/>
    <child link="right_cylinder"/>
    <origin xyz="0 0.3 0.3"/>
  </joint>


  <link name="left_cylinder">
    <visual>
     <geometry>
        <cylinder length="0.6" radius="0.1"/>
      </geometry>
      <origin xyz="0 0 0.3"/>
      <material name="pink"/>
    </visual>
  </link>

  <joint name="base_to_left_cylinder" type="revolute">
    <axis xyz="1 0 0"/>
    <limit effort="1000.0" lower="0.0" upper="0.7" velocity="0.5"/>
    <parent link="base_link"/>
    <child link="left_cylinder"/>
    <origin xyz="0 -0.3 0.3"/>
  </joint>

  <link name="up_box">
    <visual>
     <geometry>
        <box size ="0.2 0.3 0.2"/>
      </geometry>
      <origin xyz="0.1 0 0"/>
      <material name="white"/>
    </visual>
  </link>

  <joint name="base_to_up_box" type="prismatic">
    <axis xyz="0 0 1"/>
    <limit effort="1000.0" lower="-0.2" upper="0.2" velocity="0.2"/>
    <parent link="base_link"/>
    <child link="up_box"/>
    <origin xyz="0.3 0 0"/>
  </joint>

  <link name="sphere">
    <visual>
     <geometry>
        <sphere radius ="0.1"/>
      </geometry>
      <origin xyz="0.1 0 0"/>
      <material name="pink"/>
    </visual>
  </link>

  <joint name="up_box_to_sphere" type="fixed">
    <parent link="up_box"/>
    <child link="sphere"/>
    <origin xyz="0.2 0 0"/>
  </joint>

</robot>
